"""
Test error handling and recovery scenarios.
Tests circuit breaker, graceful degradation, and error recovery.
"""

import pytest
import asyncio
from unittest.mock import Mock, AsyncMock, patch

from main import (
    EnhancedErrorHandler as ErrorHandler,
    ErrorType,
    CircuitBreaker,
    EnhancedAppContext as AppContext,
    reflectivethinking,
    toolselectthinking,
    reflectivereview,
)
from pydantic import ValidationError as ThoughtValidationError


class CircuitBreakerError(Exception):
    """Circuit breaker error for testing."""

    pass


class TestCircuitBreaker:
    """Test the CircuitBreaker implementation."""

    def test_circuit_breaker_initialization(self):
        """Test CircuitBreaker initialization."""
        cb = CircuitBreaker(failure_threshold=3, recovery_timeout=60)

        assert cb.failure_threshold == 3
        assert cb.recovery_timeout == 60
        assert cb.failure_count == 0
        assert cb.last_failure_time is None
        assert not cb.is_open

    def test_circuit_breaker_success_flow(self):
        """Test circuit breaker with successful calls."""
        cb = CircuitBreaker()

        # Successful calls should not trip the breaker
        for _ in range(10):
            # Successful operation
            cb.record_success()

        assert not cb.is_open
        assert cb.failure_count == 0

    def test_circuit_breaker_failure_threshold(self):
        """Test circuit breaker trips after threshold."""
        cb = CircuitBreaker(failure_threshold=3)

        # Cause failures
        for i in range(3):
            try:
                try:
                    raise Exception("Test failure")
                except Exception:
                    cb.record_failure()
            except Exception:
                pass

        assert cb.is_open
        assert cb.failure_count == 3

        # Circuit should be open
        assert cb.is_open

    def test_circuit_breaker_recovery(self):
        """Test circuit breaker recovery after timeout."""
        cb = CircuitBreaker(failure_threshold=2, recovery_timeout=1)  # 1 second timeout

        # Trip the breaker
        for _ in range(2):
            try:
                try:
                    raise Exception("Test failure")
                except Exception:
                    cb.record_failure()
            except Exception:
                pass

        assert cb.is_open

        # Wait for recovery
        import time

        time.sleep(1.1)

        # Should allow retry (half-open state)
        cb.record_success()

        assert not cb.is_open
        assert cb.failure_count == 0

    def test_circuit_breaker_expected_exceptions(self):
        """Test circuit breaker only counts expected exceptions."""
        cb = CircuitBreaker()

        # Non-expected exception should not count
        try:
            try:
                raise TypeError("Not counted")
            except TypeError:
                # CircuitBreaker doesn't filter by exception type
                cb.record_failure()
        except TypeError:
            pass

        assert cb.failure_count == 1  # All exceptions count

        # Another exception
        try:
            raise ValueError("Counted")
        except ValueError:
            cb.record_failure()

        assert cb.failure_count == 2


class TestErrorHandler:
    """Test the ErrorHandler class."""

    @pytest.fixture
    def error_handler(self):
        """Create an ErrorHandler instance."""
        return ErrorHandler()

    def test_error_handler_initialization(self, error_handler):
        """Test ErrorHandler initialization."""
        assert len(error_handler.circuit_breakers) > 0
        assert ErrorType.TEAM_INITIALIZATION in error_handler.circuit_breakers
        assert ErrorType.MODEL_COMMUNICATION in error_handler.circuit_breakers

    def test_handle_known_errors(self, error_handler):
        """Test handling of known error types."""
        # Test validation error
        error = ThoughtValidationError("Invalid thought data")
        result = error_handler.handle_error(error, ErrorType.VALIDATION_ERROR)

        assert "validation error" in result.lower()
        assert "Invalid thought data" in result

    def test_handle_api_errors(self, error_handler):
        """Test handling of API errors."""
        # Test rate limit error
        error = Exception("Rate limit exceeded")
        result = error_handler.handle_error(error, ErrorType.MODEL_COMMUNICATION)

        assert "rate limit" in result.lower()

        # Test token limit error
        error = Exception("context_length_exceeded")
        result = error_handler.handle_error(error, ErrorType.MODEL_COMMUNICATION)

        assert "token limit" in result.lower()

    def test_handle_unknown_errors(self, error_handler):
        """Test handling of unknown errors."""
        error = Exception("Something unexpected happened")
        result = error_handler.handle_error(error, ErrorType.CONTEXT_ERROR)

        assert "unexpected error" in result.lower()
        assert "Something unexpected happened" in result

    def test_circuit_breaker_integration(self, error_handler):
        """Test circuit breaker integration with error handler."""
        # Cause multiple team initialization failures
        for i in range(5):
            try:
                error = Exception("Team init failed")
                error_handler.handle_error(error, ErrorType.TEAM_INITIALIZATION)
            except CircuitBreakerError as e:
                # Circuit breaker should trip after threshold
                assert "circuit breaker open" in str(e).lower()
                assert i >= 3  # Should trip after 3 failures
                break
        else:
            pytest.fail("Circuit breaker did not trip")

    # def test_get_fallback_response(self, error_handler):
    #     """Test fallback response generation."""
    #     # Team error fallback
    #     fallback = error_handler.get_fallback_response(ErrorType.TEAM_INITIALIZATION)
    #     assert "continue without team" in fallback.lower()

    #     # Tool selection fallback
    #     fallback = error_handler.get_fallback_response(ErrorType.TOOL_SELECTION_ERROR)
    #     assert "thinkingtools" in fallback.lower()

    #     # Unknown error fallback
    #     fallback = error_handler.get_fallback_response(ErrorType.CONTEXT_ERROR)
    #     assert "error occurred" in fallback.lower()


class TestMCPErrorHandling:
    """Test error handling in MCP endpoints."""

    @pytest.fixture
    def mock_failing_team(self):
        """Create a mock team that fails."""
        team = AsyncMock()
        team.arun = AsyncMock(side_effect=Exception("Team processing failed"))
        return team

    @pytest.fixture
    def mock_app_context_with_errors(self, mock_failing_team):
        """Create app context with failing components."""
        context = AppContext()

        # Set failing teams directly
        context.primary_team = mock_failing_team
        context.reflection_team = mock_failing_team
        context.teams_initialized = True
        return context

    @pytest.mark.asyncio
    async def test_reflectivethinking_handles_team_failure(
        self, mock_app_context_with_errors
    ):
        """Test reflectivethinking handles team failures gracefully."""
        with patch("main.app_context", mock_app_context_with_errors):
            result = await reflectivethinking(
                thought="Test thought",
                thoughtNumber=1,
                totalThoughts=3,
                nextThoughtNeeded=True,
            )

            # Should return error message, not crash
            assert "error" in result.lower()
            assert "team processing failed" in result.lower()

    @pytest.mark.asyncio
    async def test_reflectivethinking_validation_errors(self):
        """Test handling of validation errors."""
        context = AppContext()

        with patch("main.app_context", context):
            # Invalid thought number
            result = await reflectivethinking(
                thought="Test",
                thoughtNumber=-1,  # Invalid
                totalThoughts=5,
                nextThoughtNeeded=True,
            )

            assert "error" in result.lower()
            assert "validation" in result.lower()

            # Revision without target
            result = await reflectivethinking(
                thought="Revise",
                thoughtNumber=2,
                totalThoughts=5,
                nextThoughtNeeded=True,
                isRevision=True,
                # Missing revisesThought
            )

            assert "error" in result.lower()

    @pytest.mark.asyncio
    async def test_toolselectthinking_handles_failures(
        self, mock_app_context_with_errors
    ):
        """Test toolselectthinking handles failures gracefully."""
        with patch("main.app_context", mock_app_context_with_errors):
            result = await toolselectthinking(
                thought="Select tools for task",
                available_tools=["tool1", "tool2"],
            )

            # Should provide fallback recommendations
            assert "error" in result.lower() or "ThinkingTools" in result

    @pytest.mark.asyncio
    async def test_reflectivereview_handles_empty_session(self):
        """Test review handles empty sessions gracefully."""
        context = AppContext()

        with patch("main.app_context", context):
            result = await reflectivereview()

            # Should handle empty session
            assert "no thoughts" in result.lower() or "empty" in result.lower()

    @pytest.mark.asyncio
    async def test_api_timeout_handling(self):
        """Test handling of API timeouts."""
        context = AppContext()

        # Mock team that times out
        async def timeout_call(*args, **kwargs):
            await asyncio.sleep(10)  # Simulate long delay

        mock_team = AsyncMock()
        mock_team.arun = timeout_call
        context.primary_team = mock_team
        context.reflection_team = mock_team
        context.teams_initialized = True

        with patch("main.app_context", context):
            # This should timeout (if timeout is implemented)
            result = await reflectivethinking(
                thought="Test timeout",
                thoughtNumber=1,
                totalThoughts=1,
                nextThoughtNeeded=False,
            )

            # Should handle timeout gracefully
            assert result is not None

    @pytest.mark.asyncio
    async def test_memory_limit_handling(self):
        """Test handling of memory limits."""
        context = AppContext()

        with patch("main.app_context", context):
            # Create many thoughts to test memory limits
            for i in range(100):
                await reflectivethinking(
                    thought=f"Thought {i}" * 1000,  # Large thought
                    thoughtNumber=i + 1,
                    totalThoughts=100,
                    nextThoughtNeeded=(i < 99),
                )

            # Context should handle memory limits
            memory_usage = context.shared_context.get_memory_usage()

            # Should have enforced limits
            assert memory_usage["memory_store_items"] <= 500  # Max items
            assert memory_usage["insights_count"] <= 50  # Max insights

    @pytest.mark.asyncio
    async def test_concurrent_error_handling(self):
        """Test error handling with concurrent requests."""
        context = AppContext()

        # Mock team that fails randomly
        call_count = 0

        async def random_fail(*args, **kwargs):
            nonlocal call_count
            call_count += 1
            if call_count % 2 == 0:
                raise Exception("Random failure")
            return Mock(content="Success")

        mock_team = AsyncMock()
        mock_team.arun = random_fail
        context.primary_team = mock_team
        context.reflection_team = mock_team
        context.teams_initialized = True

        with patch("main.app_context", context):
            # Run concurrent requests
            tasks = []
            for i in range(10):
                task = reflectivethinking(
                    thought=f"Concurrent thought {i}",
                    thoughtNumber=i + 1,
                    totalThoughts=10,
                    nextThoughtNeeded=True,
                )
                tasks.append(task)

            results = await asyncio.gather(*tasks, return_exceptions=True)

            # Some should succeed, some should fail gracefully
            successes = [
                r for r in results if isinstance(r, str) and "error" not in r.lower()
            ]
            failures = [
                r for r in results if isinstance(r, str) and "error" in r.lower()
            ]

            assert len(successes) > 0
            assert len(failures) > 0
            assert len(successes) + len(failures) == 10

    @pytest.mark.asyncio
    async def test_malformed_input_handling(self):
        """Test handling of malformed inputs."""
        context = AppContext()

        with patch("main.app_context", context):
            # Test with None values
            result = await reflectivethinking(
                thought=None,  # Invalid
                thoughtNumber=1,
                totalThoughts=1,
                nextThoughtNeeded=False,
            )
            assert "error" in result.lower()

            # Test with extreme values
            result = await reflectivethinking(
                thought="Test",
                thoughtNumber=1000000,  # Very large
                totalThoughts=1,
                nextThoughtNeeded=False,
            )
            # Should adjust or error gracefully
            assert result is not None

    def test_error_type_coverage(self):
        """Test that all error types have handlers."""
        handler = ErrorHandler()

        for error_type in ErrorType:
            # Should have circuit breaker
            assert error_type.value in handler.circuit_breakers

    @pytest.mark.asyncio
    async def test_graceful_degradation(self):
        """Test system degrades gracefully under failures."""
        context = AppContext()

        # Make team initialization fail
        async def init_fail():
            raise Exception("Cannot initialize teams")

        context.initialize_teams = init_fail

        with patch("main.app_context", context):
            # Should still work without teams
            result = await reflectivethinking(
                thought="Test without teams",
                thoughtNumber=1,
                totalThoughts=1,
                nextThoughtNeeded=False,
            )

            # Should provide some response
            assert result is not None
            assert len(result) > 0


# TODO: Create various scenario tests
# - Test cascading failures (one component failure triggers others)
# - Test partial failures (some agents work, others fail)
# - Test recovery after extended downtime
# - Test error accumulation over time
# - Test different LLM provider failures
# - Test network partition scenarios
# - Test resource exhaustion (CPU, memory)

# TODO: Create various edge case tests
# - Test with corrupted state files
# - Test with invalid JSON responses
# - Test with infinite loops in thought processing
# - Test with circular thought dependencies
# - Test with conflicting revision chains
# - Test with byzantine failures (inconsistent responses)
# - Test with clock skew issues
